Workbook

Sheet Contract Info
B2: Contract No.:
B3: Registration No.:
B4: Project Description:
B5: Borough:
B6: Contractor:
B7: Resident Engineer:

Sheet Sketch Cont
B12: Contract No: | G12: ='Contract Info'!C2 | M12: Reg. No: | P12: ='Contract Info'!C3
B13: Project Description: | I13: ='Contract Info'!C4
B15: Borough:
B17: Inspector's Name:
F19: Date: | Q19: I.R. No.: | U19: __________ | AA19: Sheet No.: ____ of ____
C20: Day of Week: | I20: S | J20: M | K20: T | L20: W | M20: T | N20: F | O20: S
N61: Reviewed by:
C62: Inspector's Signature | S62: Resident Engineer's Name | AF62: Date

Sheet Report Cont
F10: Date: | Q10: I.R. No.: | U10: __________ | AA10: Sheet No.: ____ of ____
C11: Day of Week: | I11: S | J11: M | K11: T | L11: W | M11: T | N11: F | O11: S
B14: Contract No: | G14: ='Contract Info'!C2 | M14: Reg. No: | P14: ='Contract Info'!C3
B15: Project Description: | I15: ='Contract Info'!C4
B17: Borough:
B19: Inspector's Name:
N49: Reviewed by:
C50: Inspector's Signature | S50: Resident Engineer's Name | AF50: Date

Sheet Gen Fr
AF4: Date:
AD5: Day of Week: | AI5: S | AJ5: M | AK5: T | AL5: W | AM5: T | AN5: F | AO5: S
AD6: I.R. No.:
B8: Contract No: | G8: ='Contract Info'!C2 | M8: Reg. No: | P8: ='Contract Info'!C3 | AC8: Sheet No.: | AH8: 1 | AK8: of | AM8: 1
B10: Project Description: | I10: ='Contract Info'!C4 | Z10: Work Activity Time: | AG10: ( Start ________ End ________ )
B12: Borough: | F12: ='Contract Info'!C5 | AA12: Inspector Time: | AG12: ( Start ________ End ________ )
Y13: Daily Temp. | AD13: Low | AI13: oF | AK13: High | AP13: oF
B14: Contractor: | F14: ='Contract Info'!C6
Y15: General Weather Conditions | AD15: AM | AK15: PM
B17: Inspector's Name:
B20: DESCRIPTION OF WORK PERFORMED AND INSPECTED
B21: Specify for Each Operation: Item No., Subcontractor (if any), Location, Nature of Work, Results and Details.
AD36: Reverse page used for additional remarks.
B38: ITEM NO. | G38: BUDGET CODE | N38: PAY QUANTITY | S38: QUANTITY CHK (Initials) | X38: DESCRIPTION OF ITEM
B51: Inspector's Report - General Rev. 10/31/03

Sheet Gen Bk
B2: Comments, Visitors, Other Work / Sketches:
AA27: Continued on next page (if any).
B29: End of the Day MPT/Safety Check List | N29: Y | P29: N | R29: REMARKS:
B30: Plastic Barrels
B31: Pedestrian Barricades
B32: Timber Curbs
B33: Timber/Breakaway Barricades
B34: General Safety Conditions
B35: Local Emergency Access
B36: Fencing
B37: Plates
B38: Arrow Board
B39: Site Cleaned and Secured
B41: WORK FORCE | I41: EQUIPMENT
B42: Type | G42: No. | I42: Type | N42: Model / Size | V42: No. | Y42: Model / Size | AG42: No.
B43: Superintendent | I43: Front End Loader
B44: Foremen | I44: Backhoe
B45: Operators | I45: Crane
B46: Laborers | I46: Truck (Dump)
B47: Flaggers | I47: Roller
B48: Carpenters | I48: Compressor
B49: Timbermen | I49: Excavator
B50: Masons | I50: Trailers
B51: Teamsters | I51: Pavement Cutter
I52: Tampers
B55: The above described work was incorporated into this project and was constructed in conformance with all plans, specifications, and standards unless otherwise noted.
N59: Reviewed by:
C60: Inspector's Signature | S60: Resident Engineer's Signature | AE60: Date
B61: Inspector's Report - General (Page 2) Rev. 10/31/03

Sheet SWR Fr
AF7: Date:
AD8: Day of Week: | AI8: S | AJ8: M | AK8: T | AL8: W | AM8: T | AN8: F | AO8: S
AD9: IR No.:
B11: Contract No: | G11: ='Contract Info'!C2 | M11: Reg. No: | P11: ='Contract Info'!C3 | AC11: Sheet No.: | AK11: of
B13: Project Description: | I13: ='Contract Info'!C4 | Z13: Work Activity Time: | AG13: ( Start ________ End ________ )
B15: Borough: | F15: ='Contract Info'!C5 | AB15: Inspector Time: | AG15: ( Start ________ End ________ )
Y16: Daily Temp. | AC16: Low | AH16: oF | AJ16: High | AO16: oF
B17: Contractor: | F17: ='Contract Info'!C6
Y18: General Weather Conditions | AC18: AM | AJ18: PM
B20: Inspector's Name:
C22: General Activity:
C23: Location:
B25: DETAILED ACTIVITIES | J25: From Station | P25: To Station | V25: DETAILS | AN25: Sub A or B
B26: Saw Cut
B27: Pavement Removed | V27: Width | AB27: Type / Thickness
B29: Trench Excavated | V29: Pilot Cut Depth | AD29: Total Depth | AJ29: Width
V30: Size/Type of Sewer Removed:
B32: Trench Sheeted | V32: In conformance with approved shop drawings | AJ32: Y | AL32: N
V33: Type | AC33: Size
B35: Subgrade Compaction | V35: Density Tests: List all stations / %
V36: Compaction Eqpt. Used
B38: Stone Ballast Placed | V38: Size / Type | Z38: / | AB38: Total Depth | AH38: Pay Depth
B40: Pipe Placed | V40: Size | AA40: Type | AF40: Lab Number(s)
V41: Pay Length
B43: Cradle Poured | V43: Cylinder #'s
B44: Full Encasement | V44: C.Y.'s Poured | AD44: All spurs encased | AK44: Y | AM44: N
B46: Pipe Placed | V46: Size | AA46: Type | AE46: Lab Number(s)
V47: Pay Length
B49: Cradle Poured | V49: Cylinder #'s
B50: Full Encasement | V50: C.Y.'s Poured | AD50: All spurs encased | AK50: Y | AM50: N
B52: Manhole Placed | M52: At station: | W52: Poured in Place | AC52: Precast | AJ52: Pipe encased at | AL52: Y
B53: No. | V53: Type | AA53: Diameter | AJ53: MH connection | AL53: N
B55: Manhole Placed | M55: At station: | W55: Poured in Place | AC55: Precast | AJ55: Pipe encased at | AL55: Y
B56: No. | V56: Type | AA56: Diameter | AJ56: MH connection | AL56: N
B58: Manhole Placed | M58: At station: | W58: Poured in Place | AC58: Precast | AJ58: Pipe encased at | AL58: Y
B59: No. | V59: Type | AA59: Diameter | AJ59: MH connection | AL59: N
B61: Backfilled with 2ft Select Granular
B63: Trench Backfilling and Compaction | V63: Clean Backfill | AB63: Existing Material
V64: Compaction Eqpt. Used | AC64: Per Spec. or Appvd. Alternate | AK64: Y | AM64: N
V65: Depth of Lifts | AC65: Attach Compaction Test Field Report
...

Sheet SWR Bk
B2: Comments, visitors, other work, etc.
B28: Subcontractor A is
B29: Subcontractor B is
B30: Contractor's Equipment In Use | G30: Model/ Size | K30: Prime No. | M30: Sub-A No. | O30: Sub-B No. | Q30: Item No. / Budget Code | V30: Pay Quantity | Z30: Quantity Chk (Initials) | AC30: Description of Item
B31: Excavator
B32: Front End Loader
B33: Backhoe
B34: Truck (Dump)
B36: Work Force
B37: Superintendent
B38: Foremen
B39: Operators
B40: Timbermen
B41: Laborers
B42: Teamster
B47: The above described work was incorporated into this project and was constructed in conformance with all plans, specifications, and standards unless otherwise noted.
N51: Reviewed by:
C52: Inspector's Signature | S52: Resident Engineer's Signature | AF52: Date
B53: Inspector's Report - Sewer (Page 2) Rev. 10/31/03

Sheet Conc Mix
B8: Contract No: | G8: ='Contract Info'!C2 | M8: Reg. No: | P8: ='Contract Info'!C3 | AA8: DATE:
B10: Project Description: | I10: ='Contract Info'!C4 | AA10: PAGE : | AH10: OF
B12: Borough: | F12: ='Contract Info'!C5
B14: Contractor: | F14: ='Contract Info'!C6
B17: Inspector's Name: | Y17: ATTACHMENT TO I.R. NO.:
B20: Location of Use:
C22: Curb: | J22: Sidewalk: | R22: Concrete Base: | AB22: Structural:
C25: Mixer Type: | J25: Ready Mix | U25: Other
B27: Truck or Ticket No | G27: Inspection Sticker | K27: Load Size C.Y. | N27: End Batch | Q27: Mixing Revs. | T27: Start Disch. Time | W27: End Disch. Time | Z27: Slump | AC27: Air Content if Applicable | AH27: Conc. Temp. | AK27: Cylinder Numbers
G28: Y | I28: N
G29: Y | I29: N
G30: Y | I30: N
G31: Y | I31: N
G32: Y | I32: N
G33: Y | I33: N
G34: Y | I34: N
G35: Y | I35: N
G36: Y | I36: N
G37: Y | I37: N
G38: Y | I38: N
B40: CONCRETE SPECIFICATIONS: | P40: MATERIAL USAGE:
B41: Class of Concrete: ________________ | P41: Batch Report No. | V41: = | AA41: Quantity Dispatched from Plant | AK41: =
B42: TESTS: | H42: Min | L42: Max | P42: No. of Tickets | V42: = | AA42: Quantity Received | AK42: =
B43: Slump | P43: First Ticket No. | V43: = | AA43: Quantity Used | AK43: =
B44: Air | P44: Last Ticket No. | V44: = | AA44: Quantity Wasted/Rejected | AK44: =
B47: (FILL OUT "DATA SHEET FOR CONCRETE TEST CYLINDERS")
C49: REMARKS:
B55: THIS REPORT IS NOT REQUIRED FOR DEP PIPE CRADLE/ENCASEMENT
B57: The above described work was incorporated into this project and was constructed in conformance with all plans, specifications, and standards unless otherwise noted.
Q60: Reviewed By:
C61: Inspector's Signature | W61: Resident Engineer's Name | AK61: Date
B62: Concrete Truck and Mixing Information Rev. 10/31/03

Sheet HC Fr
AF4: Date:
AD5: Day of week: | AI5: S | AJ5: M | AK5: T | AL5: W | AM5: T | AN5: F | AO5: S
AD6: I.R. No.:
B8: Contract No: | G8: ='Contract Info'!C2 | M8: Reg. No: | P8: ='Contract Info'!C3 | AC8: Sheet No.: | AK8: of
B10: Project Description: | I10: ='Contract Info'!C4 | AF10: Work Activity Time: | AG10: ( Start _______ End _______ )
B12: Borough: | F12: ='Contract Info'!C5 | AF12: Inspector Time: | AG12: ( Start _______ End _______ )
Y13: Daily Temp. | AD13: Low | AI13: oF | AK13: High | AO13: oF
B14: Contractor: | F14: ='Contract Info'!C6
Y15: General Weather Condition | AD15: AM | AK15: PM
B17: Inspector Name:
B20: DESCRIPTION OF WORK PERFORMED AND INSPECTED
B21: Specify for Each Operation: Item No., Subcontractor (if any), Location, Nature of Work, Results and Details
C23: Address: | AA23: Block: | AJ23: Lot:
C25: Sewer: | F25: Location: | Q25: Size / Type: | AC25: Spur Location:
AC26: (from downstream M.H.)
C28: Pavement Removed: | J28: Length | Q28: Width | X28: Thickness
C30: Trench Excavated: | J30: Length | Q30: Width | X30: Pilot Cut Depth | AG30: Total Depth
C32: Sheeting Installed: | J32: Size / Type | W32: Conforms with approved shop drawing: | AL32: Y | AO32: N
C35: Stone Ballast Placed: | J35: Size | W35: Thickness
C37: Pipe Placed: | J37: Size / Type | W37: Lab #'s | AH37: Pay Length
C39: Concrete Poured: | J39: Quantity | Q39: Strength | X39: Cyl. #'s | AF39: Cradle | AK39: Encasement
C42: Trench Backfilled: | I42: Select Granular (2' above pipe) | T42: Y | V42: N | X42: Rest of Trench: | AF42: Clean Backfill | AL42: Existing Material
C44: Compaction: | J44: Compaction Eqpt. Used | Y44: Per Spec. or Approved Alternate: | AL44: Y | AO44: N
J46: Depth of Lifts
C48: Temp. asphalt placed: | J48: Thickness | W48: Tons
J50: 6" Broken Stone Subbase Installed: | W50: Y | Z50: N | AC50: Compaction Eqpt. Used
B52: If temp. asphalt is to be left as permanent base, complete Inspector's Report - Asphaltic Concrete
C54: New House Connection: | N54: Depth at Curb | X54: V. F. | AB54: Distance Inside Curb | AN54: L. F.
J56: Upstream Offset | U56: L. F. | X56: Type of Approved Plugs Used
B58: H.C. THEORETICAL + ACTUAL DEPTH | U58: PAY ITEMS INSTALLED TODAY
U59: Item No./ Budjet Code | Z59: Pay Quantity | AE59: Quantity Chk(Initials) | AJ59: Description of Item
B61: 1). TRAP ELEVATION:
B62: 2). DISTANCE - TRAP TO CURB:
B63: 3). MINIMUM SLOPE: | L63: 0.25 IN/FT
B65: INVERT EL. (MAX) OF NEW H.C. AT CURB:
B66: [1-(2X3)]=_____________ REQUIRED DEPTH OF
L67: H.C. AT CURB________
B68: ACTUAL DEPTH OF NEW H.C. AT CURB:
I69: =___________________
B70: Inspector's Report - New House Connection Rev. 10/31/03

Sheet HC Bk
B2: PLAN | S2: PROFILE
C21: Comments, visitors, other work, etc.:
B29: End of the Day MPT/Safety Check List | N29: Y | P29: N | R29: REMARKS:
B30: Plastic Barrels
B31: Pedestrian Barricades
B32: Timber Curbs
B33: Timber/Breakaway Barricades
B34: General Safety Conditions
B35: Local and Emergency Access
B36: Fencing
B37: Plates
B38: Arrow Board
B39: Site Cleaned and Secured
B41: Work Force | I41: EQUIPMENT
B42: Type | G42: No. | I42: Type | N42: Model / Size | V42: No. | Y42: Model / Size | AG42: No.
B43: Superintendent | I43: Front End Loader
B44: Foremen | I44: Backhoe
B45: Operators | I45: Compressor
B46: Laborers | I46: Truck (Dump)
B47: Flaggers | I47: Excavator
B48: Teamsters
B49: Surveyors
B50: Masons
B55: The above described work was incorporated into this project and was constructed in conformance with all plans, specifications, and standards unless otherwise noted.
N59: Reviewed by:
C60: Inspector's Signature | S60: Resident Engineer's Name | AE60: Date
B61: Inspector's Report - New House Connection (Page 2) Rev. 10/31/03

Sheet WM Fr 1
AF4: Date:
AD5: Day of Week: | AI5: S | AJ5: M | AK5: T | AL5: W | AM5: T | AN5: F | AO5: S
AD6: I.R. No.:
B8: Contract No: | G8: ='Contract Info'!C2 | M8: Reg. No: | P8: ='Contract Info'!C3 | AC8: Sheet No.: | AK8: of
B10: Project Description: | I10: ='Contract Info'!C4 | AF10: Work Activity Time: | AG10: ( Start ________ End ________ )
B12: Borough: | F12: ='Contract Info'!C5 | AF12: Inspector Time: | AG12: ( Start ________ End ________ )
Y13: Daily Temp. | AD13: Low | AI13: oF | AK13: High | AO13: oF
B14: Contractor: | F14: ='Contract Info'!C6
Y15: General Weather Conditions | AD15: AM | AK15: PM
B17: Inspector's Name:
C19: General Activity:
C20: Location:
B21: Subcontractor (if any):
B23: DETAILED ACTIVITIES | K23: From Sta. | O23: To Sta. | S23: DETAILS
B24: Saw cut
B25: Pavement removed
S26: Width: | AB26: Type/Thickness:
B28: Trench excavated
S29: Width: | AC29: Depth:
B31: Trench sheeted
V32: Sheeting required | AF32: Not required
B34: Trench backfilled and compacted
B35: Temp. pavement
S36: Ave. width | AC36: Min. thickness
B38: Other
B52: Material Requisitioned:
B57: All pipes visually inspected prior to installation? | X57: Yes | AC57: No
B59: Water Off Time | L59: Water On Time | V59: Informed DEP
AB60: Name | AM60: Time

Sheet WM Bk 1
B2: PROCEDURE | I2: Y | J2: N | K2: REMARKS | R2: PROCEDURE | Z2: Y | AA2: N | AB2: REMARKS
B3: Sample Taken | R3: Leakage Test
B4: Pipe Cleaned and Flushed | S4: Open Joint
B5: Chlorine Spray | S5: Pressure
C6: On Site | R6: Flushing (end of the day)
C7: Used | S7: 1.5" Tap
B8: Chlorine Powder | S8: Hydrant
C9: On Site | S9: Time(min)/Res. Chlorine (ppm)
C10: Qty. Used | R10: Backfill
B11: Torque Wrench | S11: Trench cleaned of debris
C12: Setting | S12: Material used to 1' above pipe
C13: Used | S13: Material used for remainder
B14: Pipe Plugs | R14: Lab Tech. Present
C15: On Site | S15: Name of Lab Tech.
C16: Size | R16: Backfill Compacted
B17: Pipe Supports | S17: No. of lifts
C18: Sand Bags | S18: Equipment Used
C19: Other (explain)
B23: WORK FORCE | I23: EQUIPMENT
B24: Type | G24: No. | I24: Type | N24: Model / Size | U24: No. | W24: Hrs | Y24: Model / Size | AF24: No. | AH24: Hrs
B25: Superintendent | I25: Front End Loader
B26: Foremen | I26: Backhoe
B27: Operators | I27: Crane
B28: Laborers | I28: Truck (Dump)
B29: Flaggers | I29: Roller
B30: Carpenters | I30: Compressor
B31: Timbermen | I31: Excavator
B32: Masons | I32: Trailers
B33: Teamsters | I33: Pavement Cutter
I34: Tampers
B38: End of the Day MPT/Safety Check List | N38: Y | P38: N | R38: REMARKS:
B39: Plastic Barrels
B40: Pedestrian Barricades
B41: Timber Curbs
B42: Timber/Breakaway Barricades
B43: General Safety Conditions
B44: Local Emergency Access
B45: Fencing
B46: Plates
B47: Arrow Board
...

Sheet WM Fr 2
F3: Date: | Q3: I.R. No.: | U3: __________ | Z3: Sheet No.: ____ of ____
C4: Day of Week: | I4: S | J4: M | K4: T | L4: W | M4: T | N4: F | O4: S
B6: ADDRESS | J6: TAP or W.C. / SIZE | N6: COVER | R6: LOCATION | X6: SERVICE | AF6: Length of New Service
X7: New | AB7: Existing
W54: Additional sketches on page 4
N58: Reviewed by:
C59: Inspector's Signature | S59: Resident Engineer's Name | AE59: Date

Sheet WM Bk 2

Sheet WM Fr 3
F3: Date: | AM3: I.R. No.: | AQ3: __________ | AV3: Sheet No.: ____ of ____
C4: Day of Week: | I4: S | J4: M | K4: T | L4: W | M4: T | N4: F | O4: S
B6: F.C. No. | D6: Straight Pipe | I6: M.J. Fittings | Q6: Station Start | X6: Station End | AE6: Lengths | AZ6: Weights
AE7: F&D | AL7: Laying | AS7: Allowance | AZ7: F&D M.J.
X25: Total Pay Qtys:
AL26: use reverse side for additional information
B27: ITEM No. | F27: BUDGET CODE | K27: PAY QUANTITY | P27: QUANTITY CHK (Initials) | U27: DESCRIPTION OF ITEM
AI48: Reviewed by:
G49: Inspector's Signature | AN49: Resident Engineer's Name | AZ49: Date

Sheet WM Bk 3
F3: Date: | AM3: I.R. No.: | AQ3: __________ | AV3: Sheet No.: ____ of ____
C4: Day of Week: | I4: S | J4: M | K4: T | L4: W | M4: T | N4: F | O4: S
B6: F.C. No. | D6: Straight Pipe | I6: M.J. Fittings | Q6: Station Start | X6: Station End | AE6: Lengths | AZ6: Weights
AE7: F&D | AL7: Laying | AS7: Allowance | AZ7: F&D M.J.
X25: Total Pay Qtys:
AL26: use reverse side for additional information
B27: ITEM No. | F27: BUDGET CODE | K27: PAY QUANTITY | P27: QUANTITY CHK (Initials) | U27: DESCRIPTION OF ITEM
AI48: Reviewed by:
G49: Inspector's Signature | AN49: Resident Engineer's Name | AZ49: Date

Sheet AC Fr
AF4: Date:
AD5: Day of Week: | AI5: S | AJ5: M | AK5: T | AL5: W | AM5: T | AN5: F | AO5: S
AD6: I.R. No.:
B8: Contract No: | G8: ='Contract Info'!C2 | M8: Reg. No: | P8: ='Contract Info'!C3 | AC8: Sheet No.: | AK8: of
B10: Project Description: | I10: ='Contract Info'!C4 | AF10: Work Activity Time: | AG10: ( Start ________ End ________ )
B12: Borough: | F12: ='Contract Info'!C5 | AF12: Inspector Time: | AG12: ( Start ________ End ________ )
Y13: Daily Temp. | AD13: Low | AI13: oF | AK13: High | AO13: oF
B14: Contractor: | F14: ='Contract Info'!C6
Y15: General Weather Conditions | AD15: AM | AK15: PM
B17: Inspector's Name:
B20: Name of Paving Contractor: | AA20: TEMPERATURE
D21: Subcontractor (if any): | AA21: SURFACE | AI21: AMBIENT
B22: Rice No. (Specific Gravity): | AA22: START | AE22: FINISH | AI22: START | AM22: FINISH
L23: (Contractor to Supply)
B25: THEORETICAL MAX DENSITY (FROM A/C PLANT) | W25: TOP: | AE25: BINDER:
B26: Item No. | G26: Mix Type | K26: Station | Q26: Lane | T26: Length | W26: Width | AA26: Course | AE26: Design Depth | AI26: Area (S.Y.) | AM26: Weight (Tons)
K27: From | N27: To
B33: MATERIAL USAGE (TOP): | V33: MATERIAL USAGE (BINDER):
B34: No. of Tickets | G34: = | K34: Quantity Received | R34: = | V34: No. of Tickets | AA34: = | AE34: Quantity Received | AL34: =
B35: First Ticket No. | G35: = | K35: Quantity Used | R35: = | V35: First Ticket No. | AA35: = | AE35: Quantity Used | AL35: =
B36: Last Ticket No. | G36: = | K36: Qnty Wasted/Rejected | R36: = | V36: Last Ticket No. | AA36: = | AE36: Qnty Wasted/Rejected | AL36: =
B38: ITEM NO. | F38: BUDGET CODE | K38: PAY QUANTITY | P38: QUANTITY CHK (Initials) | U38: DESCRIPTION OF ITEM
G50: REQUIREMENTS:
B51: SUBGRADE COMPACTED PER SPEC.OR APPROVED ALTERNATIVE
B52: ROADWAY SUBGRADE/BASE SURFACE SUFFICIENTLY CLEAN AND DRY
B53: A/C ROLLER AS PER SPEC. OR APPROVED PLAN
B54: DENSITY TESTS TAKEN
B55: SPOT CHECK A/C DEPTH
B56: TACK COAT APPLIED AS PER SPEC.
B57: TACK COAT APPLIED ON ALL EDGES OF HARDWARE
B58: QUANTITY OF TACK COAT: | U58: No. of Gallons: | AE58: Gallons per S.Y.:
B61: Tack Coat Application Method / Type:
B63: Inspector's Report - Asphaltic Concrete Rev. 10/31/03

Sheet AC Bk
C3: Remarks:
C4: Comments, Visitors, Other Work, Etc.
B19: Work Force | I19: EQUIPMENT
B20: Type | G20: No. | I20: Type | N20: Model / Size | V20: No. | Y20: Model / Size | AG20: No.
B21: Superintendent | I21: Front End Loader
B22: Foremen | I22: Backhoe
B23: Operators | I23: Crane
B24: Laborers | I24: Paving Machine
B25: Flaggers | I25: AC Distributor
B26: Teamsters | I26: Sweepers
B27: Surveyors | I27: Trailers
B28: Masons | I28: Truck (Dump)
I29: Roller - Static
I30: Roller - Dynamic
I31: Compressor
I32: Hand Tamper
B35: End of the Day MPT/Safety Check List | L35: Y | N35: N | P35: LOCATION | AD35: Ticket No. | AG35: Temperature
B36: Plastic Barrels
B37: Pedestrian Barricades
B38: Timber Curbs
B39: Timber/Breakaway Barricades
B40: General Safety Conditions
B41: Local and Emergency Access
B42: Fencing
B43: Plates
B44: Arrow Board
B45: Site Cleaned and Secured
D48: Attached Pages for Additional Remarks and / or Sketches
B51: The above described work was incorporated into this project and was constructed in conformance with all plans, specifications, and standards unless otherwise noted.
N55: Reviewed by:
C56: Inspector's Signature | S56: Resident Engineer's Name | AE56: Date
B57: Inspector's Report - Aphaltic Concrete (Page 2) Rev. 10/31/03

Sheet Conc Fr
AF4: Date:
AD5: Day of Week: | AI5: S | AJ5: M | AK5: T | AL5: W | AM5: T | AN5: F | AO5: S
AD6: I.R. No.:
B8: Contract No: | G8: ='Contract Info'!C2 | M8: Reg. No: | P8: ='Contract Info'!C3 | AC8: Sheet No.: | AK8: of
B10: Project Description: | I10: ='Contract Info'!C4 | AF10: Work Activity Time: | AG10: ( Start ________ End ________ )
B12: Borough: | F12: ='Contract Info'!C5 | AF12: Inspector Time: | AG12: ( Start ________ End ________ )
Y13: Daily Temp. | AD13: Low | AI13: oF | AK13: High | AO13: oF
B14: Contractor: | F14: ='Contract Info'!C6
Y15: General Weather Conditions | AD15: AM | AK15: PM
B17: Inspector's Name:
B20: DESCRIPTION OF WORK PERFORMED AND INSPECTED
B21: Specify for Each Operation: Item No., Subcontractor (if any), Location, Nature of Work, Hot/Cold weather Protection and Details
C29: Curb | H29: Sidewalk | N29: Concrete Base | V29: Structural | AC29: Subcontractor (if any)
B30: Attach concrete truck and mixing information
B32: Detailed Activity | L32: From Station | R32: To Station | X32: Remarks
B33: Excavation
B34: Form / Prep.
B35: Pour
X38: BASE | AD38: SIDEWALK | AJ38: CURB
X39: YES | Z39: NO | AB39: N/A | AD39: YES | AF39: NO | AH39: N/A | AJ39: YES | AL39: NO | AN39: N/A
B40: SUBGRADE COMPACTED:
B41: COMPACTION TEST TAKEN:
B42: SIDEWALK 6" FOUNDATION MATERIAL PLACED AND COMPACTED:
B43: ROADWAY STONE BASE PLACED AND COMPACTED:
B44: CURING COMPOUND APPLIED:
B45: OTHER CURING METHODS:
B46: WAS REBAR INSTALLED IN ACCORDANCE WITH APPROVED SHOP DRAWINGS AND BENDING SCHEDULE?:
B48: ITEM NO. | F48: BUDGET CODE | K48: PAY QUANTITY | P48: QUANTITY CHK (Initials) | U48: DESCRIPTION OF ITEM
B62: Inspector's Report - Curb, Sidewalk, Concrete Base Rev. 10/31/03

Sheet Conc Bk
B3: Work Force | I3: EQUIPMENT
B4: Type | G4: No. | I4: Type | N4: Model / Size | V4: No. | Y4: Model / Size | AG4: No.
B5: Superintendent | I5: Front End Loader
B6: Foremen | I6: Backhoe
B7: Operators | I7: Crane
B8: Laborers | I8: Paving Machine
B9: Flaggers | I9: AC Distributor
B10: Teamsters | I10: Sweepers
B11: Surveyors | I11: Trailers
B12: Masons | I12: Truck (Dump)
I13: Roller - Static
I14: Roller - Dynamic
I15: Compressor
I16: Hand Tamper
C19: Remarks:
C37: Note: See Attached "Concrete Truck and Mixing Information" Report
B39: End of the Day MPT/Safety Check List | N39: Y | P39: N | R39: REMARKS:
B40: Plastic Barrels
B41: Pedestrian Barricades
B42: Timber Curbs
B43: Timber/Breakaway Barricades
B44: General Safety Conditions
B45: Local and Emergency Access
B46: Fencing
B47: Plates
B48: Arrow Board
B49: Site Cleaned and Secured
D52: Attached Pages for Additional Remarks / Sketches / Calculations
B55: The above described work was incorporated into this project and was constructed in conformance with all plans, specifications, and standards unless otherwise noted.
N59: Reviewed by:
C60: Inspector's Signature | S60: Resident Engineer's Name | AE60: Date
B61: Inspector's Report - Curb, Sidewalk, Concrete Base (Page 2) Rev. 10/31/03

Sheet Box Fr
AF4: Date:
AD5: Day of Week: | AI5: S | AJ5: M | AK5: T | AL5: W | AM5: T | AN5: F | AO5: S
AD6: IR No.:
B8: Contract No: | G8: ='Contract Info'!C2 | M8: Reg. No: | P8: ='Contract Info'!C3 | AC8: Sheet No.: | AK8: of
B10: Project Description: | I10: ='Contract Info'!C4 | AF10: Work Activity Time: | AG10: ( Start ________ End ________ )
B12: Borough: | F12: ='Contract Info'!C5 | AF12: Inspector Time: | AG12: ( Start ________ End ________ )
Y13: Daily Temp. | AC13: Low | AH13: oF | AJ13: High | AO13: oF
B14: Contractor: | F14: ='Contract Info'!C6
Y15: General Weather Conditions | AC15: AM | AJ15: PM
B17: Inspector's Name:
C19: General Activity:
C20: Location:
B22: DETAILED ACTIVITIES | J22: From Station | P22: To Station | V22: DETAILS | AN22: Sub A or B
B23: Saw Cut
B24: Pavement Removed | V24: Width | AB24: Type / Thickness
B26: Trench Excavated | V26: Pilot Cut Depth | AD26: Total Depth | AJ26: Width
V27: Size/Type of Sewer Removed:
B29: Trench Sheeted | V29: In conformance with approved shop drawings | AJ29: Y | AL29: N
V30: Type | AC30: Size
B32: Subgrade Compaction | V32: Density Tests: List all stations / %
V33: Compaction Eqpt. Used
B35: Stone Ballast Placed | V35: Size / Type | AC35: Total Depth | AI35: Pay Depth
B37: Pipe Placed | V37: Size | Z37: Type | AE37: Lab Number(s)
V38: Pay Length
B40: Cradle Poured | V40: Cylinder #'s
B41: Full Encasement | V41: C.Y.'s Poured | AD41: All spurs encased | AK41: Y | AM41: N
B43: Manhole Placed | M43: At station: | W43: Poured in Place | AC43: Precast | AJ43: Pipe encased at | AL43: Y
B44: No. | V44: Type | AA44: Diameter | AJ44: MH connection | AL44: N
B46: Manhole Placed | M46: At station: | W46: Poured in Place | AC46: Precast | AJ46: Pipe encased at | AL46: Y
B47: No. | V47: Type | AA47: Diameter | AJ47: MH connection | AL47: N
B49: BOX SEWER | C49: Invert Rebar Placed
C50: Wall Rebar Placed
C51: Roof Rebar Placed
C52: Invert Poured | V52: See Attached - Concrete Truk and Mixing Info.
C53: Walls Poured | V53: See Attached - Concrete Truk and Mixing Info.
C54: Roof Poured | V54: See Attached - Concrete Truk and Mixing Info.
B55: Backfilled with 2ft Select Granular
B57: Trench Backfilling and Compaction | V57: Clean Backfill | AB57: Existing Material
V58: Compaction Eqpt. Used | AC58: Per Spec. or Appvd. Alternate | AK58: Y | AM58: N
V59: Depth of Lifts | AC59: Attach Compaction Test Field Report
...

Sheet Box Bk
B2: Comments, visitors, other work, etc.
B28: Subcontractor A is
B29: Subcontractor B is
B30: Contractor's Equipment In Use | G30: Model/ Size | K30: Prime No. | M30: Sub-A No. | O30: Sub-B No. | Q30: Item No. / Budget Code | U30: Pay Quantity | Y30: Quantity Chk (Initials) | AB30: Description of Item
B31: Excavator
B32: Front End Loader
B33: Backhoe
B34: Truck (Dump)
B36: Work Force
B37: Superintendent
B38: Foremen
B39: Operators
B40: Timbermen
B41: Laborers
B42: Teamster
B47: The above described work was incorporated into this project and was constructed in conformance with all plans, specifications, and standards unless otherwise noted.
N51: Reviewed by:
C52: Inspector's Signature | S52: Resident Engineer's Signature | AE52: Date
B53: Inspector's Report - Box Sewer (Page 2) Rev. 10/31/03

Sheet Pile Fr
AF4: Date:
AD5: Day of Week: | AI5: S | AJ5: M | AK5: T | AL5: W | AM5: T | AN5: F | AO5: S
AC6: I.R. No.:
B8: Contract No: | G8: ='Contract Info'!C2 | M8: Reg. No: | P8: ='Contract Info'!C3 | AC8: Sheet No.: | AK8: of
B10: Project Description: | I10: ='Contract Info'!C4 | Z10: Work Activity Time: | AG10: ( Start ________ End ________ )
B12: Borough: | F12: ='Contract Info'!C5 | AB12: Inspector Time: | AG12: ( Start ________ End ________ )
Y13: Daily Temp. | AD13: Low | AI13: oF | AK13: High | AP13: oF
B14: Contractor: | F14: ='Contract Info'!C6
Y15: General Weather Conditions | AD15: AM | AK15: PM
B17: Inspector's Name:
C20: DESCRIPTION OF WORK PERFORMED AND INSPECTED
C21: Specify for Each Operation: Item No., Subcontractor (if any), Location, Nature of Work, Results and Details.
B23: Subcontractor A is:
B25: Subcontractor B is:
V26: Test Pile Driven | AL26: Y | AO26: N
B28: Equipment | J28: Model / Size | N28: Prime | Q28: Sub A | S28: Sub B | V28: Pile Plan Approval Received | AL28: Y | AO28: N
V30: Piles - Material / Size / Design Bearing Capacity:
V32: Timber Piles Creosote Treated | AI32: Y | AL32: N | AO32: N/A
V34: Hammer - Type / Size: | AM34: Foot Pounds
V36: Cushion Block - Type / Dimensions
V38: Design Refusal - (Blows / Last Foot)
V40: Approved Pile Driving Equipment: | AL40: Y | AO40: N
V42: All Piles visually inspected prior to installation | AL42: Y | AO42: N
V44: Vibration Monitoring in place | AL44: Y | AO44: N
V46: Note: Piles must start and end at a manhole
B48: Work Force | J48: No. | V48: PAY ITEMS INSTALLED TODAY
B49: Superintendent | V49: Item No. / Budget Code | AB49: Pay Quantity | AE49: Quantity Chk (Initials) | AH49: Description of Item
B50: Foreman
B51: Operators
B52: Carpenters
B53: Laborers
B54: Iron Workers
B55: Teamsters
B57: (Comments, visitors, other work, etc.):
B60: End of the Day MPT/Safety Check List | Q60: Y | S60: N | U60: REMARKS
B61: Plastic Barrels
B62: Pedestrian Barricades
B63: Timber Curbs
B64: Timber/Breakaway Barricades
B65: General Safety Conditions
...

Sheet Pile Bk
B2: LOCATION:
B3: STATION:
B4: PILE #:
F5: BLOWS PER FOOT
B6: PENETRATION BELOW SUBGRADE IN FEET
B36: LENGTH
B37: CUT OFF
B38: PAY LENGTH
B39: NOTE: SKETCH WILL BE DRAWN WHEN ALL PILES HAVE BEEN INSTALLED
B40: Inspector's Report - Pile Driving (Page 2) Rev. 10/31/03

Sheet Jack Fr
AF4: Date:
AD5: Day of Week: | AI5: S | AJ5: M | AK5: T | AL5: W | AM5: T | AN5: F | AO5: S
AD6: I.R. No.:
B8: Contract No: | G8: ='Contract Info'!C2 | M8: Reg. No: | P8: ='Contract Info'!C3 | AC8: Sheet No.: | AK8: of
B10: Project Description: | I10: ='Contract Info'!C4 | AF10: Work Activity Time: | AG10: ( Start ________ End ________ )
B12: Borough: | F12: ='Contract Info'!C5 | AF12: Inspector Time: | AG12: ( Start ________ End ________ )
Y13: Daily Temp. | AD13: Low | AI13: oF | AK13: High | AP13: oF
B14: Contractor: | F14: ='Contract Info'!C6
Y15: General Weather Conditions | AD15: AM | AK15: PM
B17: Inspector Name:
C21: 1. EXCAVATION | AD21: 6. PIPE MEASUREMENT
AD22: (Diameter 6" from Bell)
R23: [3.0 CY] | W23: [4.0 CY]
AD24: PIPE No. | AH24: VERTICAL | AL24: HORIZONTAL
D25: Number of muck carts removed:
D27: Estimate of actual excavation (muck volumes): | Z27: CY
D29: Jacking length: | Z29: LF
D31: Theoretical excavation quantity: | Z31: CY
D33: Excess quantity (take precaution if excessive): | Z33: CY
C36: 2. SOIL TYPE
D38: DESCRIPTION:
D40: Boulders ( Number and Size): | T40: Payment Size:
D42: Location: | K42: Station: | P42: + | T42: Quadrant:
D44: Time spent on removal of boulder:
D46: Existence of water:
C49: 3. BENTONITE / GROUTING
O50: BENTONITE | W50: GROUTING
D52: Quantity applied:
D54: Point of application: | L54: Station: | Q54: + | T54: Station: | Y54: +
C57: 4. JACKING PRESSURE: | R57: (Not to exceed)
C60: 5. DEVIATION IN ALIGNMENT: | P60: Vertical | V60: Horizontal
Z63: TOTAL No. OF PIPE INSTALLED TODAY:
B65: Inspector's Report - Jacking Rev. 10/31/03

Sheet Jack Bk
B2: 7. COMMENTS Polling, Breasting and Equipment Downtime:
C27: CHAMBER 1 | AE27: CHAMBER 2
E39: Attached pages for additional remarks and/or Sketches.
B42: The above described work was incorporated into this project and was constructed in conformance with all plans, specifications, and standards unless otherwise noted.
N46: Reviewed by:
C47: Inspector's Signature | S47: Resident Engineer's Signature | AE47: Date
B48: Inspector's Report - Jacking (Page 2) Rev. 10/31/03

Sheet CCL Fr
AF4: Date:
AD5: Day of Week: | AI5: S | AJ5: M | AK5: T | AL5: W | AM5: T | AN5: F | AO5: S
B8: Contract No: | G8: ='Contract Info'!C2 | M8: Reg. No: | P8: ='Contract Info'!C3 | AD8: Log #:
B10: Project Description: | I10: ='Contract Info'!C4 | AB10: Complaint Code(s):
B12: Borough: | F12: ='Contract Info'!C5
B14: Contractor: | F14: ='Contract Info'!C6
B17: Community Liaison: | N17: Company:
C20: COMPLAINANT'S NAME:
C21: COMPLAINANT'S ADDRESS:
C24: COMPLAINANT'S PHONE: | L24: AM | N24: ( ) | W24: PM | Y24: ( ) | AG24: FAX | AI24: ( )
E26: SITE VISIT | S26: MAIL | AH26: OTHER
E28: TELEPHONE | S28: OFFICE VISIT
E30: COMMUNITY BOARD / DISTRICT MANAGER | S30: MEETING ATTENDANCE
C33: COMMENTS:
AE41: Continued on next page (if any)
C44: RESPONSE: | K44: CORRECTED | X44: REFERRED:
C45: (INDICATE DATE) | AC45: (e.g., Punch List, DDC, Other Agency, etc.)
K46: CB NOTIFIED
B49: COMPLAINT CODES
B50: 001 | D50: General Information | P50: 005 | R50: Safety | AC50: 009 | AE50: Transit
B51: 002 | D51: House Keeping | P51: 006 | R51: Sewer | AC51: 010 | AE51: Sidewalk Violation
B52: 003 | D52: Landscaping / Trees / Environmental Concerns | P52: 007 | R52: Catch Basin | AC52: 011 | AE52: Signage / Street Marking
B53: 004 | D53: Noise / Vibration | P53: 008 | R53: Service Interruption (water, electric, gas) | AC53: 012 | AE53: Access (Building / Driveway)
T57: Reviewed By:
C58: CCL's Signature | N58: Phone Number | Z58: Resident Engineer's Signature | AM58: Date
B59: Community Construction Liaison - Project Complaint Rev. 10/31/03

Sheet CCL Bk
B2: COMMENTS CONTINUED:
B37: Community Construction Liaison - Project Complaint (Page 2) Rev. 10/31/03

Sheet RE Fr
AF7: Date:
AD8: Day of Week: | AI8: S | AJ8: M | AK8: T | AL8: W | AM8: T | AN8: F | AO8: S
B10: Contract No: | G10: ='Contract Info'!C2 | M10: Reg. No: | P10: ='Contract Info'!C3 | AC10: Sheet No.: | AK10: of
B12: Project Description: | I12: ='Contract Info'!C4 | Z12: Work Activity Time: | AG12: ( Start ________ End ________ )
B14: Borough: | F14: ='Contract Info'!C5 | AA14: Res. Engr. Time: | AG14: ( Start ________ End ________ )
Y15: Daily Temp. | AD15: Low | AI15: oF | AK15: High | AO15: oF
B16: Contractor: | F16: ='Contract Info'!C6
Y17: General Weather Conditions | AD17: AM | AK17: PM
B19: Resident Engineer's Name: | K19: ='Contract Info'!C7
C22: Major Contract Operations:
B23: I.R. No. | F23: Inspector's Name | S23: Work Assignment and Identification
B32: Was "Daily Site Patrol" performed? | P32: YES | S32: NO | X32: I.R. No.
B34: Were deficiencies noted? | P34: YES | S34: NO | X34: If not corrected was a field order issued? | AL34: YES | AO34: NO
AB36: Field Order No.
B38: Remarks, unusual event, official visitors and any non-compliance issues and actions taken.
D56: Continued on next page (if any)
Q60: Reviewed by:
C61: Resident Engineer's Signature | V61: Engineer-In-Charge's Signature | AK61: Date
B62: RE's Daily Project Diary

Sheet RE Bk
B2: Remarks, etc., continued:
D40: Continued on next page (if any)
N44: Reviewed by:
C45: Resident Engineer's Signature | S45: Engineer-In-Charge's Signature | AE45: Date
B46: RE's Daily Project Diary (Page 2) Rev. 10/31/03

Sheet DSP Fr
B8: Contract No: | G8: ='Contract Info'!C2 | M8: Reg. No: | P8: ='Contract Info'!C3 | AG8: Date:
B10: Project Description: | I10: ='Contract Info'!C4 | AE10: Day of Week: | AK10: S | AL10: M | AM10: T | AN10: W | AO10: T | AP10: F | AQ10: S
B12: Borough: | F12: ='Contract Info'!C5 | AE12: I.R. No.:
AE13: Sheet No.: | AM13: of
B14: Contractor: | F14: ='Contract Info'!C6
AE15: Time of Patrol:
B18: Maintenance of Site | V18: YES | Y18: NO | AB18: N/A | AE18: If No, Provide Details
B19: Has waste, rubbish and debris been removed from site ?
B22: Are all open trenches plated or fully enclosed with adequate fencing ?
B25: Are all stored materials/equipment properly secured and protected ?
B28: Are all open paved areas swept clean ?
B31: Are all trees properly protected ?
B34: Is temporary pavement being maintained ?
B37: Maintenance and Protection of Traffic | V37: YES | Y37: NO | AB37: N/A | AE37: If No, Provide Details
B38: Is traffic maintained in accordance with approved traffic plan / stipulations ?
B41: Are all advance warning signs in place ?
B44: Are all required traffic control signs in place ?
B47: Are all tapers and transitions in place ?
B50: Are all required barrels in place ?
B53: Are sufficient flashing lights in place and working ?
B56: Are breakaway barricades installed where required ?
B59: Are required arrow boards in place ?
B62: Are timber curbs / concrete barriers installed where required ?
B65: Is steel pedestrian fencing in place as required ?
B68: Is pedestrian access to / from building being maintained ?
B71: Is access to all fire hydrants provided ?
... B86: I reviewed all the applicable items listed above on Daily Site Patrol this date and except as noted they were in conformance with the contract requirements.
AA87: Field Order Issued? | AJ87: Y | AL87: N
Q88: Resident Engineer | AN88: Date
B89: Daily Site Patrol Rev. 10/31/03

Sheet DSP Bk
B7: Contract No: | F7: ='Contract Info'!C2 | M7: Reg. No: | P7: ='Contract Info'!C3 | AB7: FIELD ORDER #
B9: Project Description: | H9: ='Contract Info'!C4
B11: Borough: | F11: ='Contract Info'!C5
B13: Contractor: | F13: ='Contract Info'!C6 | AB13: Date Issued:
B15: Resident Engineer's Name: | K15: ='Contract Info'!C7
C18: THE FOLLOWING DEFICIENCIES IN MAINTENANCE AND PROTECTION OF TRAFFIC AND SITE MAINTENANCE HAVE BEEN OBSERVED:
B21: LOCATION | P21: MAINTENANCE AND PROTECTION OF TRAFFIC DEFICIENCIES | AE21: Required Completion Date | AK21: Actual Date / Time Completed
B29: LOCATION | P29: MAINTENANCE OF SITE DEFICIENCIES | AE29: Required Completion Date | AK29: Actual Date / Time Completed
B37: The above deficiencies are to be completed to the satisfaction of Resident Engineer by the required completion date.
B39: Failure to comply will result in non payment of applicable contract items, assessment of penalties, and/or further actions as appropriate.
C41: Received by: | W41: Issued by:
H42: Contractor's Representative | AB42: Resident Engineer
L44: Witness: | AB44: (Only if Contractor refused to sign)
B47: AUTHORIZATION FOR PAYMENT BY ENGINEER-IN-CHARGE:
C49: I, | P49: , hereby certify that I have patrolled this project site on | AN49: and
D50: Engineer-In-Charge | AH50: Date
C51: reviewed Daily Site Patrol forms from | U51: to | AB51: . I have determined that payment for
O52: Date | V52: Date
C53: satisfactory MPT and MOS can be made for the following dates:
C54: MPT: (Dates)
C55: MOS: (Dates)
J58: Engineer-In-Charge's Signature | AH58: Date
B60: Daily Site Patrol (Page 2) Rev. 10/31/03

Sheet Off Fr
AF4: Date:
AD5: Day of Week: | AI5: S | AJ5: M | AK5: T | AL5: W | AM5: T | AN5: F | AO5: S
AD6: I.R. No.:
B8: Contract No: | G8: ='Contract Info'!C2 | M8: Reg. No: | P8: ='Contract Info'!C3 | AC8: Sheet No.: | AK8: of
B10: Project Description: | I10: ='Contract Info'!C4
B12: Borough: | F12: ='Contract Info'!C5
B14: Contractor: | F14: ='Contract Info'!C5
B17: Inspector's Name: | H17: ='Contract Info'!C7
B20: DESCRIPTION OF WORK PERFORMED AND INSPECTED
B21: Specify for Each Operation: Item No., Subcontractor (if any), Location, Nature of Work, Results and Details.
B22: Monthly Payment Report:
B23: % Work:______ mil / 10.80 mil = ______ - ______ (prev. payment) = ________ L.S.
B24: #65: MOS _______ L.S.
B25: #66: MPT _______ L.S.
B26: #78: Engineer's Field Office ______ Months
B27: #79: Transportation for the Engineer ______ F.S./Month
B28: #87: Rodent Infestation Survey & Monitoring _______ L.S.
AD36: Reverse page used for additional remarks.
B38: ITEM NO. | G38: BUDGET CODE | N38: PAY QUANTITY | S38: QUANTITY CHK (Initials) | X38: DESCRIPTION OF ITEM
B39: 65 | G39: SE-200R | X39: MOS
B40: 66 | G40: SE-200R | X40: MPT
B41: 78 | G41: SE-200R | X41: Engineer's Field Office
B42: 79 | G42: SE-200R | X42: Transportation for the Engineer
B43: 87 | G43: SE-200R | X43: Rodent Infestation Survey & Monitoring
B51: Inspector's Report - General Rev. 10/31/03

Sheet Off Bk
B2: Comments, Visitors, Other Work / Sketches:
B40: The above described work was incorporated into this project and was constructed in conformance with all plans, specifications, and standards unless otherwise noted.
N44: Reviewed by:
C45: Inspector's Signature | S45: Resident Engineer's Signature | AE45: Date
B46: Inspector's Report - General (Page 2) Rev. 10/31/03

Sheet Field Memo
B8: Contract No: | G8: ='Contract Info'!C2 | M8: Reg. No: | P8: ='Contract Info'!C3 | Z8: FIELD MEMO #
B10: Project Description: | I10: ='Contract Info'!C4
B12: Borough: | F12: ='Contract Info'!C5
B14: Contractor: | F14: ='Contract Info'!C6
B17: Resident Engineer's Name: | K17: ='Contract Info'!C7 | AA17: Date:
B41: NOTE: | E41: The order herein set forth shall not be construed as an approval for additional work, or approval of, or allowance for, additional payment unless noted work is payable under appropriate contract bid items.
C45: Received for Contractor (Signature) | AD45: Date
C48: Resident Engineer (Signature) | AD48: Date / Time
C50: FAXED TO CONTRACTOR'S MAIN OFFICE | W50: YES | AC50: NO
B60: Field Memo Rev. 10/31/03

Sheet Field Order
B8: Contract No: | G8: ='Contract Info'!C2 | M8: Reg. No: | P8: ='Contract Info'!C3 | Z8: FIELD ORDER #
B10: Project Description: | I10: ='Contract Info'!C4
B12: Borough: | F12: ='Contract Info'!C5
B14: Contractor: | F14: ='Contract Info'!C6
B17: Resident Engineer's Name: | K17: ='Contract Info'!C7 | AA17: Date Issued:
F21: THE ABOVE REFERENCED CONTRACTOR IS HEREBY DIRECTED TO:
C37: NOTE: | F37: This field order shall not be construed as an approval of, or allowance for, additional payment.
C40: Received for Contractor (Signature) | AD40: Date
C43: Resident Engineer (Signature) | AD43: Date / Time
C45: FAXED TO CONTRACTOR'S MAIN OFFICE | W45: YES | AC45: NO
C47: ACTION TAKEN BY CONTRACTOR:
C58: Resident Engineer (Signature) | AD58: Date / Time
B60: Field Order Rev. 10/31/03

Sheet Sheet2

Sheet Sheet3
